Workbook
Name INTERVENIDAS: #REF!
Name Resumen: #REF!
Name SegmentaciónDeDatos_EPS_intervenida: #N/A
Name SegmentaciónDeDatos_EPS_intervenida1: #N/A
Name SegmentaciónDeDatos_MES: #N/A

Sheet Resumen General x Edades
A1: 1 | B1: 2 | C1: 3 | D1: 4 | E1: 5 | F1: 6 | G1: 7
A3: Resumen Incapacidades año - mes
A6: Año novedad | C6: Mes Novedad | D6: Incapacidades - Cuenta por cobrar a la EPS | E6: Reintegro Eps | F6: Castigo Cartera | G6: Pendiente de Recuperación Real | I6: Dinámica
A7: 2021 | B7: 1 | C7: ene | D7: 228677850 | E7: 206812943 | F7: =21615842+249065 -> 21864907 | G7: =+D7-E7-F7 -> 0 | H7: =IFERROR(VLOOKUP(C7,I:J,2,0),0) -> 0 | K7: =+E7+H7 -> 206812943
A8: 2021 | B8: 2 | C8: Feb | D8: 167318433 | E8: 143733285 | F8: 23585148 | G8: =+D8-E8-F8 -> 0 | H8: =IFERROR(VLOOKUP(C8,I:J,2,0),0) -> 0 | K8: =+E8+H8 -> 143733285
A9: 2021 | B9: 3 | C9: Mar | D9: 139015532 | E9: 117354941 | F9: 21660591 | G9: =+D9-E9-F9 -> 0 | H9: =IFERROR(VLOOKUP(C9,I:J,2,0),0) -> 0 | K9: =+E9+H9 -> 117354941
A10: 2021 | B10: 4 | C10: Abr | D10: 138688483 | E10: 119506087 | F10: 19182396 | G10: =+D10-E10-F10 -> 0 | H10: =IFERROR(VLOOKUP(C10,I:J,2,0),0) -> 0 | K10: =+E10+H10 -> 119506087
A11: 2021 | B11: 5 | C11: May | D11: 155175611 | E11: 155175611 | G11: =+D11-E11-F11 -> 0 | H11: =IFERROR(VLOOKUP(C11,I:J,2,0),0) -> 0 | K11: =+E11+H11 -> 155175611
A12: 2021 | B12: 6 | C12: Jun | D12: 181387641 | E12: 181387641 | G12: =+D12-E12-F12 -> 0 | H12: =IFERROR(VLOOKUP(C12,I:J,2,0),0) -> 0 | K12: =+E12+H12 -> 181387641
A13: 2021 | B13: 7 | C13: Jul | D13: 194630191 | E13: 194630191 | G13: =+D13-E13-F13 -> 0 | H13: =IFERROR(VLOOKUP(C13,I:J,2,0),0) -> 0 | K13: =+E13+H13 -> 194630191
A14: 2021 | B14: 8 | C14: Ago | D14: 203817326 | E14: =199274165+1780520 -> 201054685 | H14: =IFERROR(VLOOKUP(C14,I:J,2,0),0) -> 0 | K14: =+E14+H14 -> 201054685
A15: 2021 | B15: 9 | C15: Sep | D15: 188755821 | E15: 140727323 | H15: =IFERROR(VLOOKUP(C15,I:J,2,0),0) -> 0 | K15: =+E15+H15 -> 140727323
A16: 2021 | B16: 10 | C16: Oct | D16: 171425593 | E16: 113790868 | F16: 139549274 | H16: =IFERROR(VLOOKUP(C16,I:J,2,0),0) -> 0 | K16: =+E16+H16 -> 113790868
A17: 2021 | B17: 11 | C17: Nov | D17: 174728669 | E17: 90399180 | K17: =+E17+H17 -> 90399180
A18: 2021 | B18: 12 | C18: Dic | D18: 203843172 | E18: =185721080+90853 -> 185811933 | F18: 71237318 | G18: 0 | H18: =IFERROR(VLOOKUP(C18,I:J,2,0),0) -> 0 | K18: =+E18+H18 -> 185811933
A19: Total 2021 | D19: =SUM(D7:D18) -> 2147464322 | E19: =SUM(E7:E18) -> 1850384688 | F19: =SUM(F7:F18) -> 297079634 | G19: =SUM(G7:G18) -> 0 | K19: =+E19+H19 -> 1850384688
A20: 2022 | B20: 1 | C20: ene | D20: 212488754 | E20: 196361758 | F20: 16335861 | H20: =IFERROR(VLOOKUP(C20,I:J,2,0),0) -> 0 | K20: =+E20+H20 -> 196361758
A21: 2022 | B21: 2 | C21: Feb | D21: 198437111 | E21: 131882859 | F21: 66554252 | G21: =+D21-E21-F21 -> 0 | H21: =IFERROR(VLOOKUP(C21,I:J,2,0),0) -> 0 | K21: =+E21+H21 -> 131882859
A22: 2022 | B22: 3 | C22: Mar | D22: 177775379 | E22: 112397016 | F22: 65378363 | G22: =+D22-E22-F22 -> 0 | H22: =IFERROR(VLOOKUP(C22,I:J,2,0),0) -> 0 | K22: =+E22+H22 -> 112397016
A23: 2022 | B23: 4 | C23: Abr | D23: 181086022 | E23: 160796986 | F23: 20289036 | G23: =+D23-E23-F23 -> 0 | H23: =IFERROR(VLOOKUP(C23,I:J,2,0),0) -> 0 | K23: =+E23+H23 -> 160796986
A24: 2022 | B24: 5 | C24: May | D24: 163409172 | E24: 105397211 | F24: 16106923 | G24: =+D24-E24-F24 -> 41905038 | H24: =IFERROR(VLOOKUP(C24,I:J,2,0),0) -> 0 | K24: =+E24+H24 -> 105397211
A25: 2022 | B25: 6 | C25: Jun | D25: 164138948 | E25: 164504464 | G25: 242272 | H25: =IFERROR(VLOOKUP(C25,I:J,2,0),0) -> 0 | K25: =+E25+H25 -> 164504464
A26: 2022 | B26: 7 | C26: Jul | D26: 159004265 | E26: 159004265 | G26: =+D26-E26-F26 -> 0 | H26: =IFERROR(VLOOKUP(C26,I:J,2,0),0) -> 0 | K26: =+E26+H26 -> 159004265
A27: 2022 | B27: 8 | C27: Ago | D27: 184132744 | E27: 179271571 | G27: =+D27-E27-F27 -> 4861173 | H27: =IFERROR(VLOOKUP(C27,I:J,2,0),0) -> 0 | K27: =+E27+H27 -> 179271571
A28: 2022 | B28: 9 | C28: Sep | D28: 191941491 | E28: 160653276 | G28: =+D28-E28-F28 -> 31288215 | H28: =IFERROR(VLOOKUP(C28,I:J,2,0),0) -> 0 | K28: =+E28+H28 -> 160653276
A29: 2022 | B29: 10 | C29: Oct | D29: 189131114 | E29: 142101245 | G29: =+D29-E29-F29 -> 47029869 | H29: =IFERROR(VLOOKUP(C29,I:J,2,0),0) -> 0 | K29: =+E29+H29 -> 142101245
A30: 2022 | B30: 11 | C30: Nov | D30: 185604400 | E30: 185604400 | G30: =+D30-E30-F30 -> 0 | H30: =IFERROR(VLOOKUP(C30,I:J,2,0),0) -> 0 | K30: =+E30+H30 -> 185604400
A31: 2022 | B31: 12 | C31: Dic | D31: 174083427 | E31: 153199681 | G31: =+D31-E31-F31 -> 20883746 | H31: =IFERROR(VLOOKUP(C31,I:J,2,0),0) -> 0 | K31: =+E31+H31 -> 153199681
A32: Total 2022 | D32: =SUM(D20:D31) -> 2181232827 | E32: =SUM(E20:E31) -> 1851174732 | F32: =SUM(F20:F31) -> 184664435 | G32: =SUM(G20:G31) -> 146210313 | K32: =+E32+H32 -> 1851174732
A33: 2023 | B33: 1 | C33: ene | D33: 167819373 | E33: 167819373 | G33: =+D33-E33-F33 -> 0 | H33: =IFERROR(VLOOKUP(C33,I:J,2,0),0) -> 0 | K33: =+E33+H33 -> 167819373
A34: 2023 | B34: 2 | C34: Feb | D34: 231383519 | E34: 190108513 | G34: =+D34-E34-F34 -> 41275006 | H34: =IFERROR(VLOOKUP(C34,I:J,2,0),0) -> 0 | K34: =+E34+H34 -> 190108513
A35: 2023 | B35: 3 | C35: Mar | D35: 229546462 | E35: 224985751 | G35: =+D35-E35-F35 -> 4560711 | H35: =IFERROR(VLOOKUP(C35,I:J,2,0),0) -> 0 | K35: =+E35+H35 -> 224985751
A36: 2023 | B36: 4 | C36: Abr | D36: 212201656 | E36: 172164072 | G36: =+D36-E36-F36 -> 40037584 | H36: =IFERROR(VLOOKUP(C36,I:J,2,0),0) -> 0 | K36: =+E36+H36 -> 172164072
A37: 2023 | B37: 5 | C37: May | D37: 193403835 | E37: 165824586 | G37: =+D37-E37-F37 -> 27579249 | H37: =IFERROR(VLOOKUP(C37,I:J,2,0),0) -> 0 | K37: =+E37+H37 -> 165824586
A38: 2023 | B38: 6 | C38: Jun | D38: 226660411 | E38: 155108412 | G38: =+D38-E38-F38 -> 71551999 | H38: =IFERROR(VLOOKUP(C38,I:J,2,0),0) -> 0 | K38: =+E38+H38 -> 155108412
A39: 2023 | B39: 7 | C39: Jul | D39: 245907751 | E39: 245907751 | G39: =+D39-E39-F39 -> 0 | H39: =IFERROR(VLOOKUP(C39,I:J,2,0),0) -> 0 | K39: =+E39+H39 -> 245907751
A40: 2023 | B40: 8 | C40: Ago | D40: 208099142 | E40: 191348765 | G40: =+D40-E40-F40 -> 16750377 | H40: =IFERROR(VLOOKUP(C40,I:J,2,0),0) -> 0 | K40: =+E40+H40 -> 191348765
A41: 2023 | B41: 9 | C41: Sep | D41: 206599433 | E41: 206599433 | G41: =+D41-E41-F41 -> 0 | H41: =IFERROR(VLOOKUP(C41,I:J,2,0),0) -> 0 | K41: =+E41+H41 -> 206599433
A42: 2023 | B42: 10 | C42: Oct | D42: 194176254 | E42: 190780768 | G42: =+D42-E42-F42 -> 3395486 | H42: =IFERROR(VLOOKUP(C42,I:J,2,0),0) -> 0 | K42: =+E42+H42 -> 190780768
A43: 2023 | B43: 11 | C43: Nov | D43: 179386564 | E43: 135185437 | G43: =+D43-E43-F43 -> 44201127 | H43: =IFERROR(VLOOKUP(C43,I:J,2,0),0) -> 0 | K43: =+E43+H43 -> 135185437
...

Sheet PROVISION
A4: Provisión Incapacidades por Edades
U5: 67952700
A8: Año | B8: Total Incapacidades | C8: Valores Recuperados | E8: Pendiente por Recuperar | G8: No cobrables en resultados - CASTIGO | H8: SALDO DIC 2024 | I8: Saldo CXC Enero 2025 | J8: Saldo CXC Febrero 2025 | K8: Saldo CXC Marzo 2025 | L8: Saldo CXC Abril 2025 | M8: Saldo CXC Mayo 2025 | N8: Saldo CXC Junio 2025 | O8: Saldo CXC Julio 2025 | P8: Saldo CXC Agosto 2025 | Q8: Saldo CXC Septiembre 2025 | R8: Provision Actual | S8: Exceso/ Faltante | T8: % Provision | U8: Promedio provisiones
A9: Total 2021 | B9: =+VLOOKUP(A9,'Resumen General x Edades'!A:D,4,0) -> 2147464322 | C9: =+VLOOKUP(A9,'Resumen General x Edades'!A:E,5,0) -> 1850384688 | D9: =+C9/B9 -> 0.86166027 | E9: =ROUND(B9-C9-G9,0) -> 0 | F9: =+E9/B9 -> 0 | G9: =+VLOOKUP(A9,'Resumen General x Edades'!A:F,6,0) -> 297079634 | H9: 71570443 | I9: 71479590 | J9: 71479590 | K9: 71479590 | L9: 71479590 | M9: 71479590 | N9: 0 | O9: 0 | P9: 0 | Q9: =+VLOOKUP(A9,'Resumen General x Edades'!A:G,7,0) -> 0 | R9: =791949000-17136000+9942000-3767000-159220461-3382087+68166000+69889000+68055000-139549286+126271000+143456200+139702100+186775000+67952700-9294200-184664435+3549300-51783100+79087000-27808600+35066500-15550700+4874100+M23+M22 -> 1153905731 | S9: =SUM(Q9:Q13)-R9 -> 313280958 | T9: =R14/Q14 -> 0.78647505 | U9: =SUM(Q9:Q13)/SUM(B9:B12) -> 0.1581336
A10: Total 2022 | B10: =+VLOOKUP(A10,'Resumen General x Edades'!A:D,4,0) -> 2181232827 | C10: =+VLOOKUP(A10,'Resumen General x Edades'!A:E,5,0) -> 1851174732 | D10: =+C10/B10 -> 0.84868278 | E10: =ROUND(B10-C10-G10,0) -> 145393660 | F10: =+E10/B10 -> 0.066656644 | G10: =+VLOOKUP(A10,'Resumen General x Edades'!A:F,6,0) -> 184664435 | H10: 158295669 | I10: 158295669 | J10: 158295669 | K10: 158295669 | L10: 155995669 | M10: 155962336 | N10: 156204608 | O10: 156204608 | P10: 156204608 | Q10: =+VLOOKUP(A10,'Resumen General x Edades'!A:G,7,0) -> 146210313
A11: Total 2023 | B11: =+VLOOKUP(A11,'Resumen General x Edades'!A:D,4,0) -> 2457236468 | C11: =+VLOOKUP(A11,'Resumen General x Edades'!A:E,5,0) -> 2121450256 | D11: =+C11/B11 -> 0.86334803 | E11: =ROUND(B11-C11-G11,0) -> 335786212 | F11: =+E11/B11 -> 0.13665197 | G11: =+VLOOKUP(A11,'Resumen General x Edades'!A:F,6,0) -> 0 | H11: 346716753 | I11: 346678086 | J11: 346678086 | K11: 346678086 | L11: 346400753 | M11: 345898086 | N11: 345845374 | O11: 345285528 | P11: 345218862 | Q11: =+VLOOKUP(A11,'Resumen General x Edades'!A:G,7,0) -> 335786212
A12: Total 2024 | B12: =+VLOOKUP(A12,'Resumen General x Edades'!A:D,4,0) -> 2492212944 | C12: =+VLOOKUP(A12,'Resumen General x Edades'!A:E,5,0) -> 1978603166 | D12: =+C12/B12 -> 0.79391417 | E12: =ROUND(B12-C12-G12,0) -> 513609778 | F12: =+E12/B12 -> 0.20608583 | G12: =+VLOOKUP(A12,'Resumen General x Edades'!A:F,6,0) -> 0 | H12: 941244958 | I12: 663839347 | J12: 626002165 | K12: 555207618 | L12: 543285700 | M12: 508882153 | N12: 505759412 | O12: 503279717 | P12: 500376959 | Q12: =+VLOOKUP(A12,'Resumen General x Edades'!A:G,7,0) -> 513609778
A13: Total 2025 | B13: =+VLOOKUP(A13,'Resumen General x Edades'!A:D,4,0) -> 2270699221 | C13: =+VLOOKUP(A13,'Resumen General x Edades'!A:E,5,0) -> 1799118835 | D13: =+C13/B13 -> 0.79231931 | E13: =ROUND(B13-C13-G13,0) -> 471580386 | F13: =+E13/B13 -> 0.20768069 | G13: =+VLOOKUP(A13,'Resumen General x Edades'!A:F,6,0) -> 0 | H13: 0 | I13: 237017178 | J13: 445942269 | K13: 513714245 | L13: 647887465 | M13: 666062207 | N13: 674640011 | O13: 609047351 | P13: 701052617 | Q13: =+VLOOKUP(A13,'Resumen General x Edades'!A:G,7,0) -> 471580386
A14: Totales | B14: =SUM(B9:B13) -> 11548845782 | C14: =SUM(C9:C13) -> 9600731677 | D14: =SUM(D9:D13) -> 4.1599245 | E14: =SUM(E9:E13) -> 1466370036 | F14: =SUM(F9:F13) -> 0.61707514 | G14: =SUM(G9:G13) -> 481744069 | H14: =SUM(H9:H13) -> 1517827823 | I14: 1477309870 | J14: =SUM(J9:J13) -> 1648397779 | K14: 1645375208 | L14: 1765049177 | M14: 1748284372 | N14: =SUM(N9:N13) -> 1682449405 | O14: =SUM(O9:O13) -> 1613817204 | P14: =SUM(P9:P13) -> 1702853046 | Q14: =SUM(Q9:Q13) -> 1467186689 | R14: =SUM(R9:R13) -> 1153905731 | S14: =SUM(S9:S13) -> 313280958 | T14: =SUM(T9:T13) -> 0.78647505 | U14: =SUM(U9:U13) -> 0.1581336
I19: Conciliacion mes | L19: Histórico Faltante Provision
I21: item | J21: Valor | L21: Mes | M21: Valor
I22: Sáldo nómina | J22: ='Resumen General x Edades'!G74 -> 1467186689 | L22: 45901 | M22: 34809200
I23: Saldo Contable | J23: ='Resumen General x Edades'!G75 -> 1412815123 | L23: 45870 | M23: -63482500
I24: Partidas reg. sin identificar | J24: ='Resumen General x Edades'!G76-'Resumen General x Edades'!G77 -> -54371566 | L24: 45839 | M24: 4874100
I25: Diferencia | J25: =+J22-J23+J24 -> 0 | L25: 45809 | M25: =+'Nuevo Modelo2'!I84 -> -15550700
L26: 45778 | M26: 35066500
L27: 45748 | M27: -27808600
L28: 45717 | M28: 79087000
L29: 45689 | M29: -51783100
L30: 45658 | M30: 3549300

Sheet Nuevo Modelo2
A2: MODELO INICIAL (3 CRITERIOS)
A3: 1. MODELO DE PROVISIÓN SALDO GENERAL | H3: Prov. Actual | I3: =+PROVISION!R9 -> 1153905731
A4: MODELO ECL 2025 | H4: Pérdida con Modelo | I4: Disminicion Prov mes a mes
A5: Total Cartera | B5: =SUM(B6:B11) -> 404454216
A6: 0-180 | B6: 7910541 | C6: 0.36344208 | D6: =+B6*C6 -> 2875023.5 | G6: Enero | H6: 57831458 | I6: 1.1008624e+09
A7: 181-209 | B7: 263652526 | C7: 0.36344208 | D7: =+B7*C7 -> 95822422 | G7: Febrero | H7: 64430769 | I7: 1.04248e+09
A8: 210-239 | B8: 25384117 | C8: 0.36344208 | D8: =+B8*C8 -> 9225656.2 | G8: Marzo | H8: 61831570 | I8: 1.1241662e+09
A9: 240-269 | B9: 27161138 | C9: 0.36344208 | D9: =+B9*C9 -> 9871500.4 | G9: Abril | H9: 86838136 | I9: 1.0963576e+09
A10: 270-299 | B10: 31983583 | C10: 0.24229472 | D10: =+B10*C10 -> 7749453.2 | G10: Mayo | H10: 84014618 | I10: 1.1064175e+09
A11: 300 en adelante | B11: 48362311 | C11: 0.24229472 | D11: =+B11*C11 -> 11717933 | G11: Junio | H11: 85571038 | I11: 1.0936903e+09
A12: Total Provision | D12: =+SUM(D6:D11) -> 1.3726199e+08 | G12: Julio | H12: 77071845 | I12: 1.097008e+09
G13: Agosto | H13: 85527231 | I13: 1.0335693e+09
A14: 2. CARTERA MÁS DE UN AÑO Y MÁS DE 80 MILLONES -(Cartera por cobrar de más de 1 año desglosado por eps y por saldos mayores a 80 millones. (Sobre ese saldo mirar el % castigado y aplicar a la historia de pérdida) | G14: Septiembre | H14: =+D12 -> 1.3726199e+08 | I14: =+$I$3-H14 -> 1.0166437e+09
G15: Octubre | H15: =+D14 -> 0 | I15: =+$I$3-H15 -> 1153905731
G16: Noviembre | H16: =+D15 -> 0 | I16: =+$I$3-H16 -> 1153905731
A17: EPS | B17: Cartera más de un año | C17: % castigado | D17: Valor provisión | G17: Diciembre | H17: =+D16 -> 0 | I17: =+$I$3-H17 -> 1153905731
H19: RANGOS PARA MODELO ECL
H20: 0-180 | I20: En plazo
H21: 181-209 | I21: 0-30
H22: 210-239 | I22: 31-60
H23: 240-269 | I23: 61-90
A24: Total general | B24: =+SUM(B19:B23) -> 0 | D24: =+SUM(D19:D23) -> 0 | H24: 270-299 | I24: 91-180
H25: 300 en adelante | I25: Más de 180
A26: 3 criterio. Cartera por cobrar de más de 1 año desglosado por eps y por saldos menores a 80 millones y especial (Aquí van incluidas todas las eps de liquidación e intervención) Se les debe asignar porcentaje de castigo (90-100%) de acuerdo al movimientos de cada una.
A28: EPS | B28: Cartera más de un año | C28: % castigado | D28: Valor provisión | E28: INTERVENIDAS
A29: SANITAS | B29: =F29-IFERROR(VLOOKUP(A29,'Resumen General x Edades'!$D$118:$E$131,2,0),0) -> 345646332 | C29: 0.9 | D29: =+B29*C29 -> 3.110817e+08 | E29: =IFERROR(VLOOKUP(A29,$I$37:$I$49,1,0)," ") -> SANITAS | F29: 351027111
A30: EPS SURA (ANTES SUSALUD) | B30: =F30-IFERROR(VLOOKUP(A30,'Resumen General x Edades'!$D$118:$E$131,2,0),0) -> 216308538 | C30: 0.9 | D30: =+B30*C30 -> 1.9467768e+08 | E30: =IFERROR(VLOOKUP(A30,$I$37:$I$49,1,0)," ") -> EPS SURA (ANTES SUSALUD) | F30: 216308538
A31: SALUD TOTAL | B31: =F31-IFERROR(VLOOKUP(A31,'Resumen General x Edades'!$D$118:$E$131,2,0),0) -> 137964155 | C31: 0.9 | D31: =+B31*C31 -> 1.2416774e+08 | E31: =IFERROR(VLOOKUP(A31,$I$37:$I$49,1,0)," ") | F31: 137964155
A32: FAMISANAR | B32: =F32-IFERROR(VLOOKUP(A32,'Resumen General x Edades'!$D$118:$E$131,2,0),0) -> 143469868 | C32: 0.9 | D32: =+B32*C32 -> 1.2912288e+08 | E32: =IFERROR(VLOOKUP(A32,$I$37:$I$49,1,0)," ") -> FAMISANAR | F32: 154659787
A33: NUEVA E.P.S. | B33: =F33-IFERROR(VLOOKUP(A33,'Resumen General x Edades'!$D$118:$E$131,2,0),0) -> 121341879 | C33: 0.9 | D33: =+B33*C33 -> 1.0920769e+08 | E33: =IFERROR(VLOOKUP(A33,$I$37:$I$49,1,0)," ") -> NUEVA E.P.S. | F33: 122080830 | G33: 2216570
A34: COMPENSAR | B34: =F34-IFERROR(VLOOKUP(A34,'Resumen General x Edades'!$D$118:$E$131,2,0),0) -> 50850241 | C34: 0.9 | D34: =+B34*C34 -> 45765217 | E34: =IFERROR(VLOOKUP(A34,$I$37:$I$49,1,0)," ") -> COMPENSAR | F34: 59887597
A35: ALIANSALUD EPS (ANTES COLMEDICA) | B35: =F35-IFERROR(VLOOKUP(A35,'Resumen General x Edades'!$D$118:$E$131,2,0),0) -> 35755589 | C35: 0.9 | D35: =+B35*C35 -> 32180030 | E35: =IFERROR(VLOOKUP(A35,$I$37:$I$49,1,0)," ") | F35: 35755589
A36: S.O.S. SERVICIO OCCIDENTAL DE SALUD S.A. | B36: =F36-IFERROR(VLOOKUP(A36,'Resumen General x Edades'!$D$118:$E$131,2,0),0) -> 30665850 | C36: 0.9 | D36: =+B36*C36 -> 27599265 | E36: =IFERROR(VLOOKUP(A36,$I$37:$I$49,1,0)," ") | F36: 30665850
A37: COMFENALCO VALLE | B37: =F37-IFERROR(VLOOKUP(A37,'Resumen General x Edades'!$D$118:$E$131,2,0),0) -> 30084604 | C37: 0.9 | D37: =+B37*C37 -> 27076144 | E37: =IFERROR(VLOOKUP(A37,$I$37:$I$49,1,0)," ") | F37: 30464204 | H37: 8600669427 | I37: COMPENSAR
A38: MEDIMAS EPS | B38: =F38-IFERROR(VLOOKUP(A38,'Resumen General x Edades'!$D$118:$E$131,2,0),0) -> 19582331 | C38: 0.9 | D38: =+B38*C38 -> 17624098 | E38: =IFERROR(VLOOKUP(A38,$I$37:$I$49,1,0)," ") -> MEDIMAS EPS | F38: 19582331 | H38: 8140003371 | I38: EMSSANAR
A39: COOMEVA | B39: =F39-IFERROR(VLOOKUP(A39,'Resumen General x Edades'!$D$118:$E$131,2,0),0) -> 17814953 | C39: 0.9 | D39: =+B39*C39 -> 16033458 | E39: =IFERROR(VLOOKUP(A39,$I$37:$I$49,1,0)," ") -> COOMEVA | F39: 17814953 | H39: 8000887022 | I39: EPS SURA (ANTES SUSALUD)
A40: COLPATRIA ARP | B40: =F40-IFERROR(VLOOKUP(A40,'Resumen General x Edades'!$D$118:$E$131,2,0),0) -> -5489804 | C40: 0.9 | D40: =+B40*C40 -> -4940823.6 | E40: =IFERROR(VLOOKUP(A40,$I$37:$I$49,1,0)," ") | F40: 11698830 | H40: 8300035647 | I40: FAMISANAR
A41: FOSYGA | B41: =F41-IFERROR(VLOOKUP(A41,'Resumen General x Edades'!$D$118:$E$131,2,0),0) -> 8884331 | C41: 0.9 | D41: =+B41*C41 -> 7995897.9 | E41: =IFERROR(VLOOKUP(A41,$I$37:$I$49,1,0)," ") | F41: 8884331 | H41: 8002514406 | I41: SANITAS
A42: COOSALUD EPS | B42: =F42-IFERROR(VLOOKUP(A42,'Resumen General x Edades'!$D$118:$E$131,2,0),0) -> 7758609 | C42: 0.9 | D42: =+B42*C42 -> 6982748.1 | E42: =IFERROR(VLOOKUP(A42,$I$37:$I$49,1,0)," ") | F42: 10271943 | H42: 9001562642 | I42: NUEVA E.P.S.
A43: EMSSANAR | B43: =F43-IFERROR(VLOOKUP(A43,'Resumen General x Edades'!$D$118:$E$131,2,0),0) -> 8131800 | C43: 0.9 | D43: =+B43*C43 -> 7318620 | E43: =IFERROR(VLOOKUP(A43,$I$37:$I$49,1,0)," ") -> EMSSANAR | F43: 8131800 | I43: MEDIMAS EPS
...

Sheet PRESENT 2
O3: MES
O4: JUNIO 2025
D12: =+'Nuevo Modelo2'!F152 -> 10850646013
D15: =+'Nuevo Modelo2'!C152 -> 8686694811
D17: =+'Nuevo Modelo2'!E152 -> 481744069
D21: =+'Nuevo Modelo2'!D152 -> 1467717280
F44: MES | G44: CRITERIO 1 | H44: CRITERIO 2 | I44: CRITERIO 3 | J44: TOTAL PROVISIÓN | K44: PROVISIÓN ACTUAL | L44: AJUSTE MES | M44: PROVISIÓN FINAL
F45: MARZO 2025 | G45: 61831570 | H45: 0 | I45: 1.0963578e+09 | J45: 1.1581894e+09 | K45: 1185998000 | L45: -27808600 | M45: 1158189400
F46: ABRIL 2025 | G46: 86838136 | H46: 0 | I46: 1.1064173e+09 | J46: 1.1932555e+09 | K46: 1158189000 | L46: 35066500 | M46: 1193255500
F47: MAYO 2025 | G47: 84014618 | H47: 0 | I47: 1.0936907e+09 | J47: 1.1777053e+09 | K47: 1193256000 | L47: -15550700 | M47: 1177705300
F48: JUNIO 2025 | G48: 85571038 | H48: 0 | I48: 1.0970081e+09 | J48: 1.1825791e+09 | K48: 1177705000 | L48: 4874100 | M48: 1182579100 | O48: =VLOOKUP(O4,'Nuevo Modelo2'!C81:M88,11,0) -> 0.80572677
F49: JULIO 2025 | G49: 77071845 | H49: 0 | I49: 1.0420247e+09 | J49: 1.1190965e+09 | K49: 1182579000 | L49: -63482500 | M49: 1119096500
F50: AGOSTO 2025 | G50: 85527231 | H50: 0 | I50: 1.068379e+09 | J50: 1.1539062e+09 | K50: 1119097000 | L50: 34809200 | M50: 1153906200
F51: SEPTIEMBRE 2025 | G51: 1.3726199e+08 | H51: 0 | I51: 1.0919764e+09 | J51: 1.2292384e+09 | K51: 75332400 | L51: 75332400 | M51: 1229238400
G59: G | I59: CRITERIO 1 | J59: CRITERIO 2 | K59: CRITERIO 3
I60: RANGOS PARA MODELO ECL
L66: CONCEPTO | M66: VALOR | N66: %
L67: Total cartera EPS Int. | M67: =+'Nuevo Modelo2'!D187 -> 923145942 | N67: =+M67/PROVISION!$J$23 -> 0.65340888
L70: Total Provision EPS Int. | M70: ='Nuevo Modelo2'!E187 -> 8.3083135e+08 | N70: =+M70/M67 -> 0.9

Sheet Hoja1
A1: MES | B1: CARTERA | C1: % | D1: Recaudo | E1: % | F1: CRITERIO 1 | G1: CRITERIO 2 | H1: CRITERIO 3 | I1: TOTAL PROVISIÓN | J1: PROVISIÓN ACTUAL | K1: AJUSTE MES | L1: PROVISIÓN FINAL | M1: %
A2: ENERO | B2: 1408205062 | D2: 205615651 | F2: 3.9255657e+08 | G2: 128415454 | H2: 60473832 | I2: 581446000 | J2: 774813000 | K2: 9942000 | L2: 784755000
A3: FEBRERO | B3: 1378619137 | C3: =(B3-B2)/B3 -> -0.02146055 | D3: 224465967 | E3: =(D3-D2)/D3 -> 0.083978504 | F3: 3.8765172e+08 | G3: 128415454 | H3: 61611475 | I3: 577679000 | J3: 784755000 | K3: -3767000 | L3: 780988000 | M3: =(L3-L2)/L3 -> -0.0048233776
A4: MARZO | B4: 1287184695 | C4: =(B4-B3)/B4 -> -0.071034438 | D4: 122330374 | E4: =(D4-D3)/D4 -> -0.83491605 | F4: 3.7490315e+08 | G4: 68278528 | H4: 40060324 | I4: 483242000 | J4: 618385000 | K4: 68166000 | L4: 686551000 | M4: =(L4-L3)/L4 -> -0.13755278
A5: ABRIL | B5: 1281480170 | C5: =(B5-B4)/B5 -> -0.0044515125 | D5: 180618914 | E5: =(D5-D4)/D5 -> 0.32271559 | F5: 42379011 | G5: 0 | H5: 1.0818676e+09 | I5: 1.1242466e+09 | J5: 686551000 | K5: 69889000 | L5: 756440000 | M5: =(L5-L4)/L5 -> 0.092391994
A6: MAYO | B6: 1337100352 | C6: =(B6-B5)/B6 -> 0.041597612 | D6: 155720180 | E6: =(D6-D5)/D6 -> -0.15989407 | F6: 53210372 | G6: 0 | H6: 1.0711907e+09 | I6: 1.1244011e+09 | J6: 756440000 | K6: 68055000 | L6: 824495000 | M6: =(L6-L5)/L6 -> 0.082541434
A7: JUNIO | B7: 1231303460 | C7: =(B7-B6)/B7 -> -0.085922679 | D7: 183387574 | E7: =(D7-D6)/D7 -> 0.15086842 | F7: 55803331 | G7: 0 | H7: 9.684463e+08 | I7: 1.0242496e+09 | J7: 684946000 | K7: 126271000 | L7: 811217000 | M7: =(L7-L6)/L7 -> -0.016368
A8: JULIO | B8: 1315298308 | C8: =(B8-B7)/B8 -> 0.063859922 | D8: 123694311 | E8: =(D8-D7)/D8 -> -0.48258697 | F8: 46317725 | G8: 0 | H8: 1081342179 | I8: 1.1276599e+09 | J8: 811217000 | K8: 143456000 | L8: 954673200 | M8: =(L8-L7)/L8 -> 0.15026734
A9: AGOSTO | B9: 1400394588 | C9: =(B9-B8)/B9 -> 0.06076593 | D9: 165055182 | E9: =(D9-D8)/D9 -> 0.25058814 | F9: 56047794 | G9: 0 | H9: 1.1536638e+09 | I9: 1.2097116e+09 | J9: 954673000 | K9: 139702100 | L9: 1094375100 | M9: =(L9-L8)/L9 -> 0.12765449
A10: SEPTIEMBRE | B10: 1441637977 | C10: =(B10-B9)/B10 -> 0.0286087 | D10: 150154070 | E10: =(D10-D9)/D10 -> -0.099238815 | F10: 48127277 | G10: 0 | H10: 1.2330227e+09 | I10: 1224259300 | J10: 1094375000 | K10: 186775000 | L10: 1281150000 | M10: =(L10-L9)/L10 -> 0.14578691

Sheet X Año
B2: SALDO CARTERA POR AÑOS
B7: Año | C7: Total Incapacidades | D7: Valores Recuperados | F7: No cobrables en resultados - CASTIGO | H7: Saldo por Año
B8: Total 2018 | C8: 1915461888 | D8: =+E8/C8 -> 0.92594113 | E8: 1773604941 | F8: =+G8/C8 -> 0.074058872 | G8: 141856947 | H8: =+I8/C8 -> 0 | I8: =+C8-E8-G8 -> 0
B9: Total 2019 | C9: 2265339149 | D9: =+E9/C9 -> 0.9132175 | E9: 2068747351 | F9: =+G9/C9 -> 0.086782501 | G9: 1.965918e+08 | H9: =+I9/C9 -> 1.1222635e-10 | I9: =+C9-E9-G9 -> 0.25423074
B10: Total 2020 | C10: 2149518413 | D10: =+E10/C10 -> 0.8093464 | E10: 1739704993 | F10: =+G10/C10 -> 0.1906536 | G10: 409813420 | H10: =+I10/C10 -> 0 | I10: =+C10-E10-G10 -> 0
B11: Total 2021 | C11: =+VLOOKUP(B11,'Resumen General x Edades'!A:D,4,0) -> 2147464322 | D11: =+E11/C11 -> 0.86166027 | E11: =VLOOKUP(B11,'Resumen General x Edades'!A:E,5,0) -> 1850384688 | F11: =+G11/C11 -> 0.13833973 | G11: =+VLOOKUP(B11,'Resumen General x Edades'!A:F,6,0) -> 297079634 | H11: =+I11/C11 -> 0 | I11: =+C11-E11-G11 -> 0
B12: Total 2022 | C12: =+VLOOKUP(B12,'Resumen General x Edades'!A:D,4,0) -> 2181232827 | D12: =+E12/C12 -> 0.84868278 | E12: =VLOOKUP(B12,'Resumen General x Edades'!A:E,5,0) -> 1851174732 | F12: =+G12/C12 -> 0.084660579 | G12: =+VLOOKUP(B12,'Resumen General x Edades'!A:F,6,0) -> 184664435 | H12: =+I12/C12 -> 0.066656644 | I12: =+C12-E12-G12 -> 145393660
B13: Total 2023 | C13: =+VLOOKUP(B13,'Resumen General x Edades'!A:D,4,0) -> 2457236468 | D13: =+E13/C13 -> 0.86334803 | E13: =VLOOKUP(B13,'Resumen General x Edades'!A:E,5,0) -> 2121450256 | F13: =+G13/C13 -> 0 | G13: =+VLOOKUP(B13,'Resumen General x Edades'!A:F,6,0) -> 0 | H13: =+I13/C13 -> 0.13665197 | I13: =+C13-E13-G13 -> 335786212
B14: Total 2024 | C14: =+VLOOKUP(B14,'Resumen General x Edades'!A:D,4,0) -> 2492212944 | D14: =+E14/C14 -> 0.79391417 | E14: =VLOOKUP(B14,'Resumen General x Edades'!A:E,5,0) -> 1978603166 | F14: =+G14/C14 -> 0 | G14: =+VLOOKUP(B14,'Resumen General x Edades'!A:F,6,0) -> 0 | H14: =+I14/C14 -> 0.20608583 | I14: =+C14-E14-G14 -> 513609778
B15: Total 2025 | C15: =+VLOOKUP(B15,'Resumen General x Edades'!A:D,4,0) -> 2270699221 | D15: =+E15/C15 -> 0.79231931 | E15: =VLOOKUP(B15,'Resumen General x Edades'!A:E,5,0) -> 1799118835 | F15: =+G15/C15 -> 0 | G15: =+VLOOKUP(B15,'Resumen General x Edades'!A:F,6,0) -> 0 | H15: =+I15/C15 -> 0.20768069 | I15: =+C15-E15-G15 -> 471580386
B16: Totales | C16: =SUM(C8:C15) -> 17879165232 | D16: =+E16/C16 -> 0.84918892 | E16: =SUM(E8:E15) -> 15182788962 | F16: =+G16/C16 -> 0.068795507 | G16: =SUM(G8:G15) -> 1.2300062e+09 | H16: =+I16/C16 -> 0.082015576 | I16: =SUM(I8:I15) -> 1.46637e+09

Sheet X EPS
B2: SALDO CARTERA POR EPS
B7: NOMBRE | C7: 0-180 | D7: 181-209 | E7: 210-239 | F7: 240-269 | G7: 270-299 | H7: 300 en adelante | I7: TOTAL
B8: A.I.C. | H8: 23015 | I8: =+SUM(C8:H8) -> 23015
B9: ALIANSALUD EPS (ANTES COLMEDICA) | C9: 8952704 | D9: 2326559 | H9: 69174650 | I9: =+SUM(C9:H9) -> 80453913
B10: AMBUQ | H10: 0 | I10: =+SUM(C10:H10) -> 0
B11: ASMET SALUD EPS SAS | E11: 97657 | G11: 135661 | H11: 1378542 | I11: =+SUM(C11:H11) -> 1611860
B12: CAJACOPI | C12: 125206 | H12: 0 | I12: =+SUM(C12:H12) -> 125206
B13: CAJACOPI ATLANTICO | H13: 8174496 | I13: =+SUM(C13:H13) -> 8174496
B14: CAPITAL SALUD | C14: 44104 | G14: 20139 | H14: 1433852 | I14: =+SUM(C14:H14) -> 1498095
B15: CAPRESOCA | C15: 881123 | D15: 88208 | E15: 220707 | G15: 601388 | H15: 8417446 | I15: =+SUM(C15:H15) -> 10208872
B16: COLPATRIA ARP | H16: 14001291 | I16: =+SUM(C16:H16) -> 14001291
B17: COMFAMILIAR GUAJIRA | H17: 418269 | I17: =+SUM(C17:H17) -> 418269
B18: COMFAMILIAR HUILA | H18: 42223 | I18: =+SUM(C18:H18) -> 42223
B19: COMFAORIENTE | H19: 624894 | I19: =+SUM(C19:H19) -> 624894
B20: COMFENALCO VALLE | C20: 1069432 | D20: 120683 | E20: 771643 | F20: 25152 | H20: 35892792 | I20: =+SUM(C20:H20) -> 37879702
B21: COMPARTA | H21: 249118 | I21: =+SUM(C21:H21) -> 249118
B22: COMPENSAR | C22: 18957385 | D22: 2763588 | E22: 2133569 | F22: 6473375 | G22: 6038056 | H22: 78092582 | I22: =+SUM(C22:H22) -> 114458555
B23: CONVIDA | H23: 15491 | I23: =+SUM(C23:H23) -> 15491
B24: COOMEVA | H24: 20780668 | I24: =+SUM(C24:H24) -> 20780668
B25: COOSALUD EPS | C25: 2734457 | D25: 59858 | G25: 116785 | H25: 12395261 | I25: =+SUM(C25:H25) -> 15306361
B26: COOSALUD MOVILIDAD | C26: 557514 | D26: 44104 | H26: 1330780 | I26: =+SUM(C26:H26) -> 1932398
B27: DUSAKAWI | H27: 46474 | I27: =+SUM(C27:H27) -> 46474
B28: EMPRESAS PUBLICAS DE MEDELLIN DEPARTAMENTO MEDICO | C28: 47016 | E28: 66226 | G28: 32529 | H28: 97834 | I28: =+SUM(C28:H28) -> 243605
B29: EMSSANAR | C29: 107899 | G29: 80697 | H29: 9382253 | I29: =+SUM(C29:H29) -> 9570849
B30: EPS ECOOPSOS S.A.S | H30: 59131 | I30: =+SUM(C30:H30) -> 59131
B31: EPS MUTUAL SER | C31: 496375 | D31: 25228 | F31: 889736 | G31: 1234264 | H31: 3854419 | I31: =+SUM(C31:H31) -> 6500022
B32: EPS SURA (ANTES SUSALUD) | C32: 28908322 | D32: 2934238 | E32: 2294383 | F32: 8291910 | G32: 5606325 | H32: 178687546 | I32: =+SUM(C32:H32) -> 226722724
B33: FAMISANAR | C33: 27198482 | D33: 1612236 | E33: 3636498 | F33: 1685259 | G33: 475727 | H33: 156547887 | I33: =+SUM(C33:H33) -> 191156089
B34: FOSYGA | C34: 2491396 | F34: 1852374 | H34: 10914242 | I34: =+SUM(C34:H34) -> 15258012
B35: MEDIMAS EPS | H35: 22842256 | I35: =+SUM(C35:H35) -> 22842256
B36: MUTUAL SER | C36: 306109 | D36: 286979 | E36: 57369 | G36: 338684 | H36: 8142548 | I36: =+SUM(C36:H36) -> 9131689
B37: NUEVA E.P.S. | C37: 32051497 | D37: 4152336 | E37: 4750824 | F37: 3557549 | G37: 4368596 | H37: 145845612 | I37: =+SUM(C37:H37) -> 194726414
B38: NUEVA EPS MOVILIDAD | C38: 1233838 | F38: 22052 | H38: 2585570 | I38: =+SUM(C38:H38) -> 3841460
B39: S.O.S. SERVICIO OCCIDENTAL DE SALUD S.A. | C39: 401419 | D39: 155682 | E39: 695725 | F39: 1059037 | G39: 27051 | H39: 35770906 | I39: =+SUM(C39:H39) -> 38109820
B40: SALUD MIA EPS | C40: 548884 | H40: 2378990 | I40: =+SUM(C40:H40) -> 2927874
B41: SALUD TOTAL | C41: 55876514 | D41: 4089575 | E41: 18778554 | F41: 12976769 | G41: 5244108 | H41: 167336678 | I41: =+SUM(C41:H41) -> 264302198
B42: SANITAS | C42: 59779996 | D42: 14900755 | E42: 6279403 | F42: 19801311 | G42: 10665590 | H42: 296090639 | I42: =+SUM(C42:H42) -> 407517694
B43: SAVIA SALUD | H43: 887185 | I43: =+SUM(C43:H43) -> 887185
B44: SAVIA SALUD | C44: 983558 | F44: 176416 | H44: 45021 | I44: =+SUM(C44:H44) -> 1204995
B45: TOTAL | C45: =SUM(C8:C44) -> 243753230 | D45: =SUM(D8:D44) -> 33560029 | E45: =SUM(E8:E44) -> 39782558 | F45: =SUM(F8:F44) -> 56810940 | G45: =SUM(G8:G44) -> 34985600 | H45: =SUM(H8:H44) -> 1293960561 | I45: =SUM(I8:I44) -> 1702852918

Sheet Nuevo Modelo2 (2)
A2: MODELO INICIAL (3 CRITERIOS)
A3: 1. MODELO DE PROVISIÓN SALDO GENERAL | H3: Prov. Actual | I3: =+PROVISION!R9 -> 1153905731
A4: MODELO ECL 2024 | H4: Pérdida con Modelo | I4: Disminicion Prov mes a mes
A5: Total Cartera | B5: =SUM(B6:B11) -> 179783051
A6: 0-180 | B6: 13884054 | C6: 0.36344208 | D6: =+B6*C6 -> 5046049.4 | G6: Enero | H6: =+D12 -> 57831458 | I6: =+$I$3-H6 -> 1.0960743e+09
A7: 181-209 | B7: 19305538 | C7: 0.36344208 | D7: =+B7*C7 -> 7016444.9 | G7: Febrero
A8: 210-239 | B8: 39011829 | C8: 0.36344208 | D8: =+B8*C8 -> 14178540 | G8: Marzo
A9: 240-269 | B9: 45597058 | C9: 0.36344208 | D9: =+B9*C9 -> 16571890 | G9: Abril
A10: 270-299 | B10: 56717772 | C10: 0.24229472 | D10: =+B10*C10 -> 13742417 | G10: Mayo
A11: 300 en adelante | B11: 5266800 | C11: 0.24229472 | D11: =+B11*C11 -> 1276117.8 | G11: Junio
A12: Total Provision | D12: =SUM(D6:D11) -> 57831458 | G12: Julio
G13: Agosto
A14: 2. CARTERA MÁS DE UN AÑO Y MÁS DE 80 MILLONES -(Cartera por cobrar de más de 1 año desglosado por eps y por saldos mayores a 80 millones. (Sobre ese saldo mirar el % castigado y aplicar a la historia de pérdida) | G14: Septiembre
G15: Octubre
G16: Noviembre
A17: EPS | B17: Cartera más de un año | C17: % castigado | D17: Valor provisión | G17: Diciembre
H19: RANGOS PARA MODELO ECL
H20: 0-180 | I20: En plazo
H21: 181-209 | I21: 0-30
H22: 210-239 | I22: 31-60
H23: 240-269 | I23: 61-90
A24: Total general | B24: =+SUM(B19:B23) -> 0 | D24: =+SUM(D19:D23) -> 0 | H24: 270-299 | I24: 91-180
H25: 300 en adelante | I25: Más de 180
A26: 3 criterio. Cartera por cobrar de más de 1 año desglosado por eps y por saldos menores a 80 millones y especial (Aquí van incluidas todas las eps de liquidación e intervención) Se les debe asignar porcentaje de castigo (90-100%) de acuerdo al movimientos de cada una.
A28: EPS | B28: Cartera más de un año | C28: % castigado | D28: Valor provisión | E28: INTERVENIDAS
A29: SANITAS | B29: =F29-IFERROR(VLOOKUP(A29,'Resumen General x Edades'!D:E,2,0),0) -> 334380218 | C29: 0.9 | D29: =+B29*C29 -> 3.009422e+08 | E29: =IFERROR(VLOOKUP(A29,$I$37:$I$49,1,0)," ") -> SANITAS | F29: 335246885
A30: EPS SURA (ANTES SUSALUD) | B30: =F30-IFERROR(VLOOKUP(A30,'Resumen General x Edades'!D:E,2,0),0) -> 201087033 | C30: 0.9 | D30: =+B30*C30 -> 1.8097833e+08 | E30: =IFERROR(VLOOKUP(A30,$I$37:$I$49,1,0)," ") -> EPS SURA (ANTES SUSALUD) | F30: 201087033
A31: SALUD TOTAL | B31: =F31-IFERROR(VLOOKUP(A31,'Resumen General x Edades'!D:E,2,0),0) -> 105723398 | C31: 0.9 | D31: =+B31*C31 -> 95151058 | E31: =IFERROR(VLOOKUP(A31,$I$37:$I$49,1,0)," ") | F31: 105723398
A32: FAMISANAR | B32: =F32-IFERROR(VLOOKUP(A32,'Resumen General x Edades'!D:E,2,0),0) -> 163758425 | C32: 0.9 | D32: =+B32*C32 -> 1.4738258e+08 | E32: =IFERROR(VLOOKUP(A32,$I$37:$I$49,1,0)," ") -> FAMISANAR | F32: 163796244
A33: NUEVA E.P.S. | B33: =F33-IFERROR(VLOOKUP(A33,'Resumen General x Edades'!D:E,2,0),0) -> 169352181 | C33: 0.9 | D33: =+B33*C33 -> 1.5241696e+08 | E33: =IFERROR(VLOOKUP(A33,$I$37:$I$49,1,0)," ") -> NUEVA E.P.S. | F33: 170002181
A34: COMPENSAR | B34: =F34-IFERROR(VLOOKUP(A34,'Resumen General x Edades'!D:E,2,0),0) -> 98554067 | C34: 0.9 | D34: =+B34*C34 -> 88698660 | E34: =IFERROR(VLOOKUP(A34,$I$37:$I$49,1,0)," ") -> COMPENSAR | F34: 107591423
A35: ALIANSALUD EPS (ANTES COLMEDICA) | B35: =F35-IFERROR(VLOOKUP(A35,'Resumen General x Edades'!D:E,2,0),0) -> 38528935 | C35: 0.9 | D35: =+B35*C35 -> 34676042 | E35: =IFERROR(VLOOKUP(A35,$I$37:$I$49,1,0)," ") | F35: 38528935
A36: S.O.S. SERVICIO OCCIDENTAL DE SALUD S.A. | B36: =F36-IFERROR(VLOOKUP(A36,'Resumen General x Edades'!D:E,2,0),0) -> 33212106 | C36: 0.9 | D36: =+B36*C36 -> 29890895 | E36: =IFERROR(VLOOKUP(A36,$I$37:$I$49,1,0)," ") | F36: 33212106
A37: COMFENALCO VALLE | B37: =F37-IFERROR(VLOOKUP(A37,'Resumen General x Edades'!D:E,2,0),0) -> 33252061 | C37: 0.9 | D37: =+B37*C37 -> 29926855 | E37: =IFERROR(VLOOKUP(A37,$I$37:$I$49,1,0)," ") | F37: 33299511 | H37: 8600669427 | I37: COMPENSAR
A38: MEDIMAS EPS | B38: =F38-IFERROR(VLOOKUP(A38,'Resumen General x Edades'!D:E,2,0),0) -> 21984063 | C38: 0.9 | D38: =+B38*C38 -> 19785657 | E38: =IFERROR(VLOOKUP(A38,$I$37:$I$49,1,0)," ") -> MEDIMAS EPS | F38: 21984063 | H38: 8140003371 | I38: EMSSANAR
A39: COOMEVA | B39: =F39-IFERROR(VLOOKUP(A39,'Resumen General x Edades'!D:E,2,0),0) -> 19999911 | C39: 0.9 | D39: =+B39*C39 -> 17999920 | E39: =IFERROR(VLOOKUP(A39,$I$37:$I$49,1,0)," ") -> COOMEVA | F39: 19999911 | H39: 8000887022 | I39: EPS SURA (ANTES SUSALUD)
A40: COLPATRIA ARP | B40: =F40-IFERROR(VLOOKUP(A40,'Resumen General x Edades'!D:E,2,0),0) -> 173030 | C40: 0.9 | D40: =+B40*C40 -> 155727 | E40: =IFERROR(VLOOKUP(A40,$I$37:$I$49,1,0)," ") | F40: 13475253 | H40: 8300035647 | I40: FAMISANAR
A41: FOSYGA | B41: =F41-IFERROR(VLOOKUP(A41,'Resumen General x Edades'!D:E,2,0),0) -> 8238973 | C41: 0.9 | D41: =+B41*C41 -> 7415075.7 | E41: =IFERROR(VLOOKUP(A41,$I$37:$I$49,1,0)," ") | F41: 8238973 | H41: 8002514406 | I41: SANITAS
A42: COOSALUD EPS | B42: =F42-IFERROR(VLOOKUP(A42,'Resumen General x Edades'!D:E,2,0),0) -> 10880279 | C42: 0.9 | D42: =+B42*C42 -> 9792251.1 | E42: =IFERROR(VLOOKUP(A42,$I$37:$I$49,1,0)," ") | F42: 11460279 | H42: 9001562642 | I42: NUEVA E.P.S.
A43: EMSSANAR | B43: =F43-IFERROR(VLOOKUP(A43,'Resumen General x Edades'!D:E,2,0),0) -> 9533222 | C43: 0.9 | D43: =+B43*C43 -> 8579899.8 | E43: =IFERROR(VLOOKUP(A43,$I$37:$I$49,1,0)," ") -> EMSSANAR | F43: 9533222 | I43: MEDIMAS EPS
...

Sheet X Pago
B2: RESUMEN RECAUDO MES
B7: Año | C7: 1 | D7: 2 | E7: 3 | F7: 4 | G7: 5 | H7: 6 | I7: 7 | J7: 8 | K7: 9 | L7: 10 | M7: 11 | N7: 12
B8: Total 2020 | C8: 184968 | D8: 483146
B9: Total 2021 | C9: 13990236 | D9: 5927233 | E9: 11637096 | F9: 12755426 | G9: 2732913 | H9: 1780520 | I9: 3773536 | J9: 0 | K9: 242272 | L9: 242272
B10: Total 2022 | C10: 23189049 | D10: 10045515 | E10: 6245706 | F10: 5775314 | G10: 2288827 | H10: 1000000 | I10: 0 | J10: 0 | K10: 0 | L10: 0 | M10: 701873
B11: Total 2023 | C11: 112026337 | D11: 137765262 | E11: 16332187 | F11: 42245102 | G11: 18898080 | H11: 5696849 | I11: 4348949 | J11: 1677279 | K11: 38667 | L11: 38667 | M11: 36352207
B12: Total 2024 | C12: 23121913 | D12: 35347673 | E12: 75269181 | F12: 109065240 | G12: 109979614 | H12: 169098844 | I12: 106761879 | J12: 143873848 | K12: 135350270 | L12: 156749172 | M12: 126693119
B13: Pendientes | C13: 33103148 | D13: 34897138 | E13: 12846204 | F13: 10777832 | G13: 21820746 | H13: 5811361 | I13: 8809947 | J13: 19504055 | K13: 14522861 | L13: 38667 | M13: 25881682 | N13: 152384117
B14: Totales | C14: =SUM(C8:C13) -> 205615651 | D14: =SUM(D8:D13) -> 224465967 | E14: =SUM(E8:E13) -> 122330374 | F14: =SUM(F8:F13) -> 180618914 | G14: =SUM(G8:G13) -> 155720180 | H14: =SUM(H8:H13) -> 183387574 | I14: =SUM(I8:I13) -> 123694311 | J14: =SUM(J8:J13) -> 165055182 | ... N14: =SUM(N8:N13) -> 152384117

Sheet PAGOS
A1: Documento | B1: Clase de documento | C1: Texto de Cabecera | D1: Fecha de documento | E1: Fecha de contabilizacion | F1: Referencia | G1: Sociedad | H1: Norm. Pres. Ctas | I1: Posición | J1: Tipo de cuenta | K1: Cuenta | L1: Activo Fijo | M1: Sub Numero Activo Fijo | N1: Clase Movimiento AF | O1: Fecha Ref AA | P1: Indicador CME | Q1: Area Funcional | R1: Grafo | S1: Num Operacion | T1: Importe | U1: Moneda | V1: T/C | W1: Fecha Conversion | X1: Indicador impuestos | Y1: Tipo de Retencion | Z1: Ind de Retencion | AA1: Base Ret | AB1: Centro de coste | AC1: Centro de Beneficio | AD1: Elemento PEP | AE1: Orden CO | AF1: Fecha Valor | AG1: Banco Propio | AH1: ID de Cuenta | AI1: Asignacion | AJ1: Clave Ref 1 | AK1: Clave Ref 2 | AL1: Clave Ref 3 | AM1: Texto Posicion | AN1: Sociedad GL | AO1: EPS intervenida | AP1: Valor | AQ1: Mes
A2: 1 | B2: SA | C2: Reclasf. Reg | D2: 45314 | E2: 45314 | F2: Reclasf. Reg | G2: O003 | I2: 2 | J2: S | K2: 1533010002 | T2: 3499600 | U2: COP | AC2: O003001452 | AF2: 20230531 | AI2: 20230531 | AJ2: 8903030935 | AM2: PAGO DE PROV CAJA VALLE DEL CAUCA | AO2: 0 | AP2: =+ABS(T2) -> 3499600 | AQ2: =+MONTH(D2) -> 1
A3: 1 | B3: SA | C3: Pago Incap | D3: 45322 | E3: 45322 | F3: PAGO INCAP | G3: O003 | I3: 47 | J3: S | K3: 1533010002 | T3: -39028523 | U3: COP | AC3: O003001452 | AF3: 20240131 | AI3: 20240131 | AJ3: 8001309074 | AM3: PAGO DE PROV SALUD TOTAL EPS | AO3: 0 | AP3: =+ABS(T3) -> 39028523 | AQ3: =+MONTH(D3) -> 1
A4: 1 | B4: SA | C4: Pago Incap | D4: 45322 | E4: 45322 | F4: PAGO INCAP | G4: O003 | I4: 48 | J4: S | K4: 1533010002 | T4: -46914091 | U4: COP | AC4: O003001452 | AF4: 20240131 | AI4: 20240131 | AJ4: 8002514406 | AM4: PAGO INTERBANC EPS SANITAS S A | AO4: SANITAS | AP4: =+ABS(T4) -> 46914091 | AQ4: =+MONTH(D4) -> 1
A5: 1 | B5: SA | C5: Pago Incap | D5: 45322 | E5: 45322 | F5: PAGO INCAP | G5: O003 | I5: 49 | J5: S | K5: 1533010002 | T5: -3962995 | U5: COP | AC5: O003001452 | AF5: 20240131 | AI5: 20240131 | AJ5: 8050011572 | AM5: PAGO INTERBANC EPS SOS S A | AO5: 0 | AP5: =+ABS(T5) -> 3962995 | AQ5: =+MONTH(D5) -> 1
A6: 1 | B6: SA | C6: Pago Incap | D6: 45322 | E6: 45322 | F6: PAGO INCAP | G6: O003 | I6: 50 | J6: S | K6: 1533010002 | T6: -1121343 | U6: COP | AC6: O003001452 | AF6: 20240131 | AI6: 20240131 | AJ6: 8140003371 | AM6: PAGO INTERBANC EMSSANAR ENTIDA | AO6: EMSSANAR | AP6: =+ABS(T6) -> 1121343 | AQ6: =+MONTH(D6) -> 1
A7: 1 | B7: SA | C7: Pago Incap | D7: 45322 | E7: 45322 | F7: PAGO INCAP | G7: O003 | I7: 51 | J7: S | K7: 1533010002 | T7: -28827471 | U7: COP | AC7: O003001452 | AF7: 20240131 | AI7: 20240131 | AJ7: 8300035647 | AM7: PAGO INTERBANC EPS FAMISANAR S | AO7: FAMISANAR | AP7: =+ABS(T7) -> 28827471 | AQ7: =+MONTH(D7) -> 1
A8: 1 | B8: SA | C8: Pago Incap | D8: 45322 | E8: 45322 | F8: PAGO INCAP | G8: O003 | I8: 52 | J8: S | K8: 1533010002 | T8: -1342499 | U8: COP | AC8: O003001452 | AF8: 20240131 | AI8: 20240131 | AJ8: 8301138310 | AM8: PAGO DE PROV ALIANSALUD EPS | AO8: 0 | AP8: =+ABS(T8) -> 1342499 | AQ8: =+MONTH(D8) -> 1
A9: 1 | B9: SA | C9: Pago Incap | D9: 45322 | E9: 45322 | F9: PAGO INCAP | G9: O003 | I9: 53 | J9: S | K9: 1533010002 | T9: -15946683 | U9: COP | AC9: O003001452 | AF9: 20240131 | AI9: 20240131 | AJ9: 8600021839 | AM9: PAGO INTERBANC AXA COLPATRIA S | AO9: 0 | AP9: =+ABS(T9) -> 15946683 | AQ9: =+MONTH(D9) -> 1
A10: 1 | B10: SA | C10: Pago Incap | D10: 45322 | E10: 45322 | F10: PAGO INCAP | G10: O003 | I10: 54 | J10: S | K10: 1533010002 | T10: -8401543 | U10: COP | AC10: O003001452 | AF10: 20240131 | AI10: 20240131 | AJ10: 8600669427 | AM10: PAGO INTERBANC CAJA DE COMPENS | AO10: COMPENSAR | AP10: =+ABS(T10) -> 8401543 | AQ10: =+MONTH(D10) -> 1
A11: 1 | B11: SA | C11: Pago Incap | D11: 45322 | E11: 45322 | F11: PAGO INCAP | G11: O003 | I11: 55 | J11: S | K11: 1533010002 | T11: -40168602 | U11: COP | AC11: O003001452 | AF11: 20240131 | AI11: 20240131 | AJ11: 9001562642 | AM11: PAGO DE PROV NUEVA EPS S A | AO11: NUEVA E.P.S. | AP11: =+ABS(T11) -> 40168602 | AQ11: =+MONTH(D11) -> 1
A12: 1 | B12: SA | C12: Pago Incap | D12: 45322 | E12: 45322 | F12: PAGO INCAP | G12: O003 | I12: 56 | J12: S | K12: 1533010002 | T12: -3623546 | U12: COP | AC12: O003001452 | AF12: 20240131 | AI12: 20240131 | AJ12: 8000887022 | AM12: EPS SURA | AO12: EPS SURA (ANTES SUSALUD) | AP12: =+ABS(T12) -> 3623546 | AQ12: =+MONTH(D12) -> 1
A13: 1 | B13: SA | C13: Pago Incap | D13: 45322 | E13: 45322 | F13: PAGO INCAP | G13: O003 | I13: 83 | J13: S | K13: 1533010002 | T13: -5998997 | U13: COP | AC13: O003001452 | AF13: 20240131 | AI13: 20240131 | AJ13: 8903030935 | AM13: COMFENALCO VALLE | AO13: 0 | AP13: =+ABS(T13) -> 5998997 | AQ13: =+MONTH(D13) -> 1
A14: 1 | B14: SA | C14: Pago Incap | D14: 45322 | E14: 45322 | F14: PAGO INCAP | G14: O003 | I14: 84 | J14: S | K14: 1533010002 | T14: -9986886 | U14: COP | AC14: O003001452 | AF14: 20240131 | AI14: 20240131 | AJ14: 8903030935 | AM14: COMFENALCO VALLE | AO14: 0 | AP14: =+ABS(T14) -> 9986886 | AQ14: =+MONTH(D14) -> 1
A15: 1 | B15: SA | C15: Pago Incap | D15: 45322 | E15: 45322 | F15: PAGO INCAP | G15: O003 | I15: 85 | J15: S | K15: 1533010002 | T15: -292472 | U15: COP | AC15: O003001452 | AF15: 20240131 | AI15: 20240131 | AJ15: 8909049961 | AM15: EPM | AO15: 0 | AP15: =+ABS(T15) -> 292472 | AQ15: =+MONTH(D15) -> 1
A16: 1 | B16: SA | C16: Pago Incap | D16: 45351 | E16: 45351 | F16: PAGO INCAP | G16: O003 | I16: 52 | J16: S | K16: 1533010002 | T16: -42933257 | U16: COP | AC16: O003001452 | AF16: 20240229 | AI16: 20240229 | AJ16: 8000887022 | AM16: PAGO DE PROV EPS SURAMERICAN | AO16: EPS SURA (ANTES SUSALUD) | AP16: =+ABS(T16) -> 42933257 | AQ16: =+MONTH(D16) -> 2
A17: 1 | B17: SA | C17: Pago Incap | D17: 45351 | E17: 45351 | F17: PAGO INCAP | G17: O003 | I17: 53 | J17: S | K17: 1533010002 | T17: -2669518 | U17: COP | AC17: O003001452 | AF17: 20240229 | AI17: 20240229 | AJ17: 8001309074 | AM17: PAGO DE PROV SALUD TOTAL EPS | AO17: 0 | AP17: =+ABS(T17) -> 2669518 | AQ17: =+MONTH(D17) -> 2
A18: 1 | B18: SA | C18: Pago Incap | D18: 45351 | E18: 45351 | F18: PAGO INCAP | G18: O003 | I18: 54 | J18: S | K18: 1533010002 | T18: -71099032 | U18: COP | AC18: O003001452 | AF18: 20240229 | AI18: 20240229 | AJ18: 8002514406 | AM18: PAGO INTERBANC EPS SANITAS S A | AO18: SANITAS | AP18: =+ABS(T18) -> 71099032 | AQ18: =+MONTH(D18) -> 2
A19: 1 | B19: SA | C19: Pago Incap | D19: 45351 | E19: 45351 | F19: PAGO INCAP | G19: O003 | I19: 55 | J19: S | K19: 1533010002 | T19: -997911 | U19: COP | AC19: O003001452 | AF19: 20240229 | AI19: 20240229 | AJ19: 8050011572 | AM19: PAGO INTERBANC EPS SOS S A | AO19: 0 | AP19: =+ABS(T19) -> 997911 | AQ19: =+MONTH(D19) -> 2
A20: 1 | B20: SA | C20: Pago Incap | D20: 45351 | E20: 45351 | F20: PAGO INCAP | G20: O003 | I20: 56 | J20: S | K20: 1533010002 | T20: -38667 | U20: COP | AC20: O003001452 | AF20: 20240229 | AI20: 20240229 | AJ20: 8060083947 | AM20: PAGO INTERBANC MUTUAL SER EPS | AO20: 0 | AP20: =+ABS(T20) -> 38667 | AQ20: =+MONTH(D20) -> 2
A21: 1 | B21: SA | C21: Pago Incap | D21: 45351 | E21: 45351 | F21: PAGO INCAP | G21: O003 | I21: 57 | J21: S | K21: 1533010002 | T21: -2325361 | U21: COP | AC21: O003001452 | AF21: 20240229 | AI21: 20240229 | AJ21: 8140003371 | AM21: PAGO INTERBANC EMSSANAR ENTIDA | AO21: EMSSANAR | AP21: =+ABS(T21) -> 2325361 | AQ21: =+MONTH(D21) -> 2
A22: 1 | B22: SA | C22: Pago Incap | D22: 45351 | E22: 45351 | F22: PAGO INCAP | G22: O003 | I22: 58 | J22: S | K22: 1533010002 | T22: -17170822 | U22: COP | AC22: O003001452 | AF22: 20240229 | AI22: 20240229 | AJ22: 8300035647 | AM22: PAGO INTERBANC EPS FAMISANAR S | AO22: FAMISANAR | AP22: =+ABS(T22) -> 17170822 | AQ22: =+MONTH(D22) -> 2
A23: 1 | B23: SA | C23: Pago Incap | D23: 45351 | E23: 45351 | F23: PAGO INCAP | G23: O003 | I23: 59 | J23: S | K23: 1533010002 | T23: -16967412 | U23: COP | AC23: O003001452 | AF23: 20240229 | AI23: 20240229 | AJ23: 8301138310 | AM23: PAGO DE PROV ALIANSALUD EPS | AO23: 0 | AP23: =+ABS(T23) -> 16967412 | AQ23: =+MONTH(D23) -> 2
A24: 1 | B24: SA | C24: Pago Incap | D24: 45351 | E24: 45351 | F24: PAGO INCAP | G24: O003 | I24: 60 | J24: S | K24: 1533010002 | T24: -14573203 | U24: COP | AC24: O003001452 | AF24: 20240229 | AI24: 20240229 | AJ24: 8600021839 | AM24: PAGO INTERBANC AXA COLPATRIA S | AO24: 0 | AP24: =+ABS(T24) -> 14573203 | AQ24: =+MONTH(D24) -> 2
A25: 1 | B25: SA | C25: Pago Incap | D25: 45351 | E25: 45351 | F25: PAGO INCAP | G25: O003 | I25: 61 | J25: S | K25: 1533010002 | T25: -3510825 | U25: COP | AC25: O003001452 | AF25: 20240229 | AI25: 20240229 | AJ25: 8600669427 | AM25: PAGO INTERBANC CAJA DE COMPENS | AO25: COMPENSAR | AP25: =+ABS(T25) -> 3510825 | AQ25: =+MONTH(D25) -> 2
A26: 1 | B26: SA | C26: Pago Incap | D26: 45351 | E26: 45351 | F26: PAGO INCAP | G26: O003 | I26: 62 | J26: S | K26: 1533010002 | T26: -40155599 | U26: COP | AC26: O003001452 | AF26: 20240229 | AI26: 20240229 | AJ26: 9001562642 | AM26: PAGO DE PROV NUEVA EPS S A | AO26: NUEVA E.P.S. | AP26: =+ABS(T26) -> 40155599 | AQ26: =+MONTH(D26) -> 2
A27: 1 | B27: SA | C27: Pago Incap | D27: 45351 | E27: 45351 | F27: PAGO INCAP | G27: O003 | I27: 63 | J27: S | K27: 1533010002 | T27: -116001 | U27: COP | AC27: O003001452 | AF27: 20240229 | AI27: 20240229 | AJ27: 9002983729 | AM27: PAGO DE PROV CAPITAL SALUD E | AO27: 0 | AP27: =+ABS(T27) -> 116001 | AQ27: =+MONTH(D27) -> 2
A28: 1 | B28: SA | C28: Pago Incap | D28: 45351 | E28: 45351 | F28: PAGO INCAP | G28: O003 | I28: 64 | J28: S | K28: 1533010002 | T28: -1237344 | U28: COP | AC28: O003001452 | AF28: 20240229 | AI28: 20240229 | AJ28: 9006043500 | AM28: PAGO DE PROV AMA EPS S.A.S | AO28: 0 | AP28: =+ABS(T28) -> 1237344 | AQ28: =+MONTH(D28) -> 2
A29: 1 | B29: SA | C29: Pago Incap | D29: 45351 | E29: 45351 | F29: PAGO INCAP | G29: O003 | I29: 65 | J29: S | K29: 1533010002 | T29: -10671015 | U29: COP | AC29: O003001452 | AF29: 20240229 | AI29: 20240229 | AJ29: 9009142541 | AM29: PAGO INTERBANC FUNDACION SALUD | AO29: 0 | AP29: =+ABS(T29) -> 10671015 | AQ29: =+MONTH(D29) -> 2
A30: 4 | B30: SA | C30: Pago Incap | D30: 45382 | E30: 45382 | F30: PAGO INCAP | G30: O003 | I30: 237 | J30: S | K30: 1533010002 | T30: -12209087 | U30: COP | AC30: O003001452 | AF30: 20240331 | AI30: 20240331 | AJ30: 8000887022 | AM30: PAGO DE PROV EPS SURAMERICAN | AO30: EPS SURA (ANTES SUSALUD) | AP30: =+ABS(T30) -> 12209087 | AQ30: =+MONTH(D30) -> 3
A31: 4 | B31: SA | C31: Pago Incap | D31: 45382 | E31: 45382 | F31: PAGO INCAP | G31: O003 | I31: 238 | J31: S | K31: 1533010002 | T31: -6504524 | U31: COP | AC31: O003001452 | AF31: 20240331 | AI31: 20240331 | AJ31: 8001309074 | AM31: PAGO DE PROV SALUD TOTAL EPS | AO31: 0 | AP31: =+ABS(T31) -> 6504524 | AQ31: =+MONTH(D31) -> 3
A32: 4 | B32: SA | C32: Pago Incap | D32: 45382 | E32: 45382 | F32: PAGO INCAP | G32: O003 | I32: 239 | J32: S | K32: 1533010002 | T32: -3209334 | U32: COP | AC32: O003001452 | AF32: 20240331 | AI32: 20240331 | AJ32: 8002492410 | AM32: PAGO INTERBANC COOSALUD-ENTIDA | AO32: 0 | AP32: =+ABS(T32) -> 3209334 | AQ32: =+MONTH(D32) -> 3
A33: 4 | B33: SA | C33: Pago Incap | D33: 45382 | E33: 45382 | F33: PAGO INCAP | G33: O003 | I33: 240 | J33: S | K33: 1533010002 | T33: -15917110 | U33: COP | AC33: O003001452 | AF33: 20240331 | AI33: 20240331 | AJ33: 8002514406 | AM33: PAGO INTERBANC EPS SANITAS S A | AO33: SANITAS | AP33: =+ABS(T33) -> 15917110 | AQ33: =+MONTH(D33) -> 3
A34: 4 | B34: SA | C34: Pago Incap | D34: 45382 | E34: 45382 | F34: PAGO INCAP | G34: O003 | I34: 241 | J34: S | K34: 1533010002 | T34: -77334 | U34: COP | AC34: O003001452 | AF34: 20240331 | AI34: 20240331 | AJ34: 8050011572 | AM34: PAGO INTERBANC EPS SOS S A | AO34: 0 | AP34: =+ABS(T34) -> 77334 | AQ34: =+MONTH(D34) -> 3
A35: 4 | B35: SA | C35: Pago Incap | D35: 45382 | E35: 45382 | F35: PAGO INCAP | G35: O003 | I35: 242 | J35: S | K35: 1533010002 | T35: -212001 | U35: COP | AC35: O003001452 | AF35: 20240331 | AI35: 20240331 | AJ35: 8060083947 | AM35: PAGO INTERBANC MUTUAL SER EPS | AO35: 0 | AP35: =+ABS(T35) -> 212001 | AQ35: =+MONTH(D35) -> 3
A36: 4 | B36: SA | C36: Pago Incap | D36: 45382 | E36: 45382 | F36: PAGO INCAP | G36: O003 | I36: 243 | J36: S | K36: 1533010002 | T36: -16862650 | U36: COP | AC36: O003001452 | AF36: 20240331 | AI36: 20240331 | AJ36: 8300035647 | AM36: PAGO INTERBANC EPS FAMISANAR S | AO36: FAMISANAR | AP36: =+ABS(T36) -> 16862650 | AQ36: =+MONTH(D36) -> 3
A37: 4 | B37: SA | C37: Pago Incap | D37: 45382 | E37: 45382 | F37: PAGO INCAP | G37: O003 | I37: 244 | J37: S | K37: 1533010002 | T37: -22887098 | U37: COP | AC37: O003001452 | AF37: 20240331 | AI37: 20240331 | AJ37: 8301138310 | AM37: PAGO DE PROV ALIANSALUD EPS | AO37: 0 | AP37: =+ABS(T37) -> 22887098 | AQ37: =+MONTH(D37) -> 3
A38: 4 | B38: SA | C38: Pago Incap | D38: 45382 | E38: 45382 | F38: PAGO INCAP | G38: O003 | I38: 245 | J38: S | K38: 1533010002 | T38: -14001696 | U38: COP | AC38: O003001452 | AF38: 20240331 | AI38: 20240331 | AJ38: 8600021839 | AM38: PAGO INTERBANC AXA COLPATRIA S | AO38: 0 | AP38: =+ABS(T38) -> 14001696 | AQ38: =+MONTH(D38) -> 3
A39: 4 | B39: SA | C39: Pago Incap | D39: 45382 | E39: 45382 | F39: PAGO INCAP | G39: O003 | I39: 246 | J39: S | K39: 1533010002 | T39: -8704906 | U39: COP | AC39: O003001452 | AF39: 20240331 | AI39: 20240331 | AJ39: 8600669427 | AM39: PAGO INTERBANC CAJA DE COMPENS | AO39: COMPENSAR | AP39: =+ABS(T39) -> 8704906 | AQ39: =+MONTH(D39) -> 3
A40: 4 | B40: SA | C40: Pago Incap | D40: 45382 | E40: 45382 | F40: PAGO INCAP | G40: O003 | I40: 247 | J40: S | K40: 1533010002 | T40: -21704777 | U40: COP | AC40: O003001452 | AF40: 20240331 | AI40: 20240331 | AJ40: 9001562642 | AM40: PAGO DE PROV NUEVA EPS S A | AO40: NUEVA E.P.S. | AP40: =+ABS(T40) -> 21704777 | AQ40: =+MONTH(D40) -> 3
...
